<robot name="farmbot">
    <link name="link1" />
    <link name="link2" />
    <link name="link3" />
    <link name="link4" />
    <link name="link5" />
    <link name="link6" />
    <link name="link7" />
    <link name="link8" />
    <link name="link9" />
    <link name="link10" />

    <joint name="joint1" type="fixed">
    <parent link="link1"/>
    <child link="link2"/>
    <origin xyz="-2 -1 0" rpy="0 0 0" />
    </joint>

    <joint name="joint2" type="fixed">
    <parent link="link1"/>
    <child link="link3"/>
    <origin xyz="-2 1 0" rpy="0 0 0"
    </joint>

    <joint name="joint3" type="fixed">
        <parent link="link1"/>
        <child link="link4"/>
        <origin xyz="2 -1 0" rpy="0 0 0" />
    </joint>

    <joint name="joint4" type="fixed">
        <parent link="link1"/>
        <child link="link5"/>
        <origin xyz="2 1 0" rpy="0 0 0" />
    </joint>

    <joint name="joint5" type="revolute">
        <parent link="link1"/>
        <child link="link10"/>
        <origin  rpy="0 0 0" xyz="0 3 0" />
        <axis rpy="0 0 0" xyz="0 0 1" />
        <limit effort="0.1" lower="-3.1" upper="3.1" velocity="0.2"/>
    </joint>

    <joint name="joint6" type="continuous">
        <parent link="link2"/>
        <child link="link6"/>
        <origin xyz="0 -4 0" rpy="0 0 0" />
        <axis xyz="1 0 0" />
    </joint>

    <joint name="joint7" type="continuous">
        <parent link="link3"/>
        <child link="link7"/>
        <origin xyz="0 -4 0" rpy="0 0 0" />
        <axis xyz="1 0 0" />
    </joint>

    <joint name="joint8" type="continuous">
        <parent link="link4"/>
        <child link="link8"/>
        <origin xyz="0 -4 0" rpy="0 0 0" />
        <axis xyz="1 0 0" />
    </joint>

    <joint name="joint9" type="continuous">
        <parent link="link5"/>
        <child link="link9"/>
        <origin xyz="0 -4 0" rpy="0 0 0" />
        <axis xyz="1 0 0" />
    </joint>
</robot>