<robot name="farmbot">
    <link name="link1" />
    <link name="link1" />
    <link name="link2" />
    <link name="link3" />
    <link name="link4" />
    <link name="link5" />
    <link name="link6" />
    <link name="link7" />
    <link name="link8" />
    <link name="link9" />
    <link name="link10" />

    <joint name="joint1" type="continuous">
    <parent link="link1"/>
    <child link="link2"/>
    </joint>

    <joint name="joint2" type="continuous">
    <parent link="link1"/>
    <child link="link3"/>
    </joint>

    <joint name="joint3" type="continuous">
        <parent link="link3"/>
        <child link="link4"/>
    </joint>
</robot>
