<sdf version='1.10'>
  <world name='empty'>
    <physics name='1ms' type='ignored'>
      <max_step_size>0.001</max_step_size>
      <real_time_factor>1</real_time_factor>
      <real_time_update_rate>1000</real_time_update_rate>
    </physics>
    <plugin name='gz::sim::systems::Physics' filename='gz-sim-physics-system'/>
    <plugin name='gz::sim::systems::UserCommands' filename='gz-sim-user-commands-system'/>
    <plugin name='gz::sim::systems::SceneBroadcaster' filename='gz-sim-scene-broadcaster-system'/>
    <plugin name='gz::sim::systems::Contact' filename='gz-sim-contact-system'/>
    <gravity>0 0 -9.8000000000000007</gravity>
    <magnetic_field>5.5644999999999998e-06 2.2875799999999999e-05 -4.2388400000000002e-05</magnetic_field>
    <atmosphere type='adiabatic'/>
    <scene>
      <ambient>0.400000006 0.400000006 0.400000006 1</ambient>
      <background>0.699999988 0.699999988 0.699999988 1</background>
      <shadows>true</shadows>
    </scene>
    <model name='ground_plane'>
      <static>true</static>
      <link name='link'>
        <collision name='collision'>
          <geometry>
            <plane>
              <normal>0 0 1</normal>
              <size>100 100</size>
            </plane>
          </geometry>
          <surface>
            <friction>
              <ode/>
            </friction>
            <bounce/>
            <contact/>
          </surface>
        </collision>
        <visual name='visual'>
          <geometry>
            <plane>
              <normal>0 0 1</normal>
              <size>100 100</size>
            </plane>
          </geometry>
          <material>
            <ambient>0.800000012 0.800000012 0.800000012 1</ambient>
            <diffuse>0.800000012 0.800000012 0.800000012 1</diffuse>
            <specular>0.800000012 0.800000012 0.800000012 1</specular>
          </material>
        </visual>
        <pose>0 0 0 0 0 0</pose>
        <inertial>
          <pose>0 0 0 0 0 0</pose>
          <mass>1</mass>
          <inertia>
            <ixx>1</ixx>
            <ixy>0</ixy>
            <ixz>0</ixz>
            <iyy>1</iyy>
            <iyz>0</iyz>
            <izz>1</izz>
          </inertia>
        </inertial>
        <enable_wind>false</enable_wind>
      </link>
      <pose>0 0 0 0 0 0</pose>
      <self_collide>false</self_collide>
    </model>
    <model name='batmobil'>
      <link name='base_link'>
        <inertial>
          <pose>-0.66666666666666663 0 -0.0041666666666666657 0 0 0</pose>
          <mass>12</mass>
          <inertia>
            <ixx>1.075791666666666</ixx>
            <ixy>0</ixy>
            <ixz>-0.12666666666666659</ixz>
            <iyy>2.214958333333334</iyy>
            <iyz>0</iyz>
            <izz>2.1941666666666668</izz>
          </inertia>
        </inertial>
        <collision name='base_link_fixed_joint_lump__wheel_arm_left_collision'>
          <pose>-1.5 -0.050000000000000003 -0.14999999999999999 0 0 0</pose>
          <geometry>
            <box>
              <size>0.02 0.029999999999999999 0.29999999999999999</size>
            </box>
          </geometry>
          <surface>
            <friction>
              <ode/>
            </friction>
            <bounce/>
            <contact/>
          </surface>
        </collision>
        <collision name='base_link_fixed_joint_lump__wheel_arm_right_collision_1'>
          <pose>-1.5 0.050000000000000003 -0.14999999999999999 0 0 0</pose>
          <geometry>
            <box>
              <size>0.02 0.029999999999999999 0.29999999999999999</size>
            </box>
          </geometry>
          <surface>
            <friction>
              <ode/>
            </friction>
            <bounce/>
            <contact/>
          </surface>
        </collision>
        <collision name='base_link_fixed_joint_lump__chassis_collision_2'>
          <pose>-0.65000000000000002 0 0.01 0 0 0</pose>
          <geometry>
            <box>
              <size>2.1000000000000001 0.94999999999999996 0.02</size>
            </box>
          </geometry>
          <surface>
            <friction>
              <ode/>
            </friction>
            <bounce/>
            <contact/>
          </surface>
        </collision>
        <visual name='base_link_fixed_joint_lump__wheel_arm_left_visual'>
          <pose>-1.5 -0.050000000000000003 -0.14999999999999999 0 0 0</pose>
          <geometry>
            <box>
              <size>0.02 0.029999999999999999 0.29999999999999999</size>
            </box>
          </geometry>
          <material>
            <diffuse>0 0 1 1</diffuse>
            <ambient>0 0 1 1</ambient>
          </material>
        </visual>
        <visual name='base_link_fixed_joint_lump__wheel_arm_right_visual_1'>
          <pose>-1.5 0.050000000000000003 -0.14999999999999999 0 0 0</pose>
          <geometry>
            <box>
              <size>0.02 0.029999999999999999 0.29999999999999999</size>
            </box>
          </geometry>
          <material>
            <diffuse>0 0 1 1</diffuse>
            <ambient>0 0 1 1</ambient>
          </material>
        </visual>
        <visual name='base_link_fixed_joint_lump__chassis_visual_2'>
          <pose>-0.65000000000000002 0 0.01 0 0 0</pose>
          <geometry>
            <box>
              <size>2.1000000000000001 0.94999999999999996 0.02</size>
            </box>
          </geometry>
          <material>
            <diffuse>0 0 1 1</diffuse>
            <ambient>0 0 1 1</ambient>
          </material>
        </visual>
        <pose>0 0 0 0 0 0</pose>
        <enable_wind>false</enable_wind>
      </link>
      <joint name='base_to_left_wheel' type='revolute'>
        <pose>0 0 -5.5511199999999995e-17 0 0 0</pose>
        <parent>base_link</parent>
        <child>left_wheel</child>
        <axis>
          <xyz>0 0 1</xyz>
          <limit>
            <lower>-inf</lower>
            <upper>inf</upper>
            <effort>inf</effort>
            <velocity>inf</velocity>
            <stiffness>100000000</stiffness>
            <dissipation>1</dissipation>
          </limit>
          <dynamics>
            <spring_reference>0</spring_reference>
            <spring_stiffness>0</spring_stiffness>
            <damping>0.10000000000000001</damping>
            <friction>0.10000000000000001</friction>
          </dynamics>
        </axis>
      </joint>
      <link name='left_wheel'>
        <pose>8.4292300000000001e-08 0.47499999999999998 -0.099999900000000003 -1.5708 -0.013658500000000004 5.0174599998867791e-08</pose>
        <inertial>
          <pose>0 0 0 0 0 0</pose>
          <mass>1</mass>
          <inertia>
            <ixx>0.02</ixx>
            <ixy>0</ixy>
            <ixz>0</ixz>
            <iyy>0.02</iyy>
            <iyz>0</iyz>
            <izz>0.02</izz>
          </inertia>
        </inertial>
        <collision name='left_wheel_collision'>
          <pose>0 0 0 0 0 0</pose>
          <geometry>
            <cylinder>
              <length>0.23999999999999999</length>
              <radius>0.29999999999999999</radius>
            </cylinder>
          </geometry>
          <surface>
            <friction>
              <ode/>
            </friction>
            <bounce/>
            <contact/>
          </surface>
        </collision>
        <visual name='left_wheel_visual'>
          <pose>0 0 0 0 0 0</pose>
          <geometry>
            <cylinder>
              <length>0.23999999999999999</length>
              <radius>0.29999999999999999</radius>
            </cylinder>
          </geometry>
          <material>
            <diffuse>1 1 0 1</diffuse>
            <ambient>1 1 0 1</ambient>
          </material>
        </visual>
        <enable_wind>false</enable_wind>
      </link>
      <joint name='base_to_right_wheel' type='revolute'>
        <pose>0 0 -5.5511199999999995e-17 0 0 0</pose>
        <parent>base_link</parent>
        <child>right_wheel</child>
        <axis>
          <xyz>0 0 -1</xyz>
          <limit>
            <lower>-inf</lower>
            <upper>inf</upper>
            <effort>inf</effort>
            <velocity>inf</velocity>
            <stiffness>100000000</stiffness>
            <dissipation>1</dissipation>
          </limit>
          <dynamics>
            <spring_reference>0</spring_reference>
            <spring_stiffness>0</spring_stiffness>
            <damping>0.10000000000000001</damping>
            <friction>0.10000000000000001</friction>
          </dynamics>
        </axis>
      </joint>
      <link name='right_wheel'>
        <pose>8.4292499999999999e-08 -0.47499999999999998 -0.099999900000000003 1.5708 -0.013658500000000006 -5.017449999921172e-08</pose>
        <inertial>
          <pose>0 0 0 0 0 0</pose>
          <mass>1</mass>
          <inertia>
            <ixx>0.02</ixx>
            <ixy>0</ixy>
            <ixz>0</ixz>
            <iyy>0.02</iyy>
            <iyz>0</iyz>
            <izz>0.02</izz>
          </inertia>
        </inertial>
        <collision name='right_wheel_collision'>
          <pose>0 0 0 0 0 0</pose>
          <geometry>
            <cylinder>
              <length>0.23999999999999999</length>
              <radius>0.29999999999999999</radius>
            </cylinder>
          </geometry>
          <surface>
            <friction>
              <ode/>
            </friction>
            <bounce/>
            <contact/>
          </surface>
        </collision>
        <visual name='right_wheel_visual'>
          <pose>0 0 0 0 0 0</pose>
          <geometry>
            <cylinder>
              <length>0.23999999999999999</length>
              <radius>0.29999999999999999</radius>
            </cylinder>
          </geometry>
          <material>
            <diffuse>1 1 0 1</diffuse>
            <ambient>1 1 0 1</ambient>
          </material>
        </visual>
        <enable_wind>false</enable_wind>
      </link>
      <joint name='arm_to_front_wheel' type='revolute'>
        <pose>0 0 2.7755599999999997e-17 0 0 0</pose>
        <parent>base_link</parent>
        <child>front_wheel</child>
        <axis>
          <xyz>0 0 1</xyz>
          <limit>
            <lower>-inf</lower>
            <upper>inf</upper>
            <effort>inf</effort>
            <velocity>inf</velocity>
            <stiffness>100000000</stiffness>
            <dissipation>1</dissipation>
          </limit>
          <dynamics>
            <spring_reference>0</spring_reference>
            <spring_stiffness>0</spring_stiffness>
            <damping>0.10000000000000001</damping>
            <friction>0.10000000000000001</friction>
          </dynamics>
        </axis>
      </joint>
      <link name='front_wheel'>
        <pose>-1.5 -6.5197999999999997e-12 -0.29999799999999999 -1.5708 -0.05405370000000001 1.987469999927868e-07</pose>
        <inertial>
          <pose>0 0 0 0 0 0</pose>
          <mass>0.80000000000000004</mass>
          <inertia>
            <ixx>0.02</ixx>
            <ixy>0</ixy>
            <ixz>0</ixz>
            <iyy>0.02</iyy>
            <iyz>0</iyz>
            <izz>0.02</izz>
          </inertia>
        </inertial>
        <collision name='front_wheel_collision'>
          <pose>0 0 0 0 0 0</pose>
          <geometry>
            <cylinder>
              <length>0.10000000000000001</length>
              <radius>0.13</radius>
            </cylinder>
          </geometry>
          <surface>
            <friction>
              <ode/>
            </friction>
            <bounce/>
            <contact/>
          </surface>
        </collision>
        <visual name='front_wheel_visual'>
          <pose>0 0 0 0 0 0</pose>
          <geometry>
            <cylinder>
              <length>0.10000000000000001</length>
              <radius>0.13</radius>
            </cylinder>
          </geometry>
          <material>
            <diffuse>1 1 0 1</diffuse>
            <ambient>1 1 0 1</ambient>
          </material>
        </visual>
        <enable_wind>false</enable_wind>
      </link>
      <frame name='base_to_wheel_arm_left' attached_to='base_link'>
        <pose>-1.5 -0.050000000000000003 -0.14999999999999999 0 0 0</pose>
      </frame>
      <frame name='wheel_arm_left' attached_to='base_to_wheel_arm_left'>
        <pose>0 0 0 0 0 0</pose>
      </frame>
      <frame name='base_to_wheel_arm_right' attached_to='base_link'>
        <pose>-1.5 0.050000000000000003 -0.14999999999999999 0 0 0</pose>
      </frame>
      <frame name='wheel_arm_right' attached_to='base_to_wheel_arm_right'>
        <pose>0 0 0 0 0 0</pose>
      </frame>
      <frame name='chassis_joint' attached_to='base_link'>
        <pose>-1 0 0 0 0 0</pose>
      </frame>
      <frame name='chassis' attached_to='chassis_joint'>
        <pose>0 0 0 0 0 0</pose>
      </frame>
    <!-- Add DiffDrive plugin here -->
      <plugin
        filename='gz-sim-diff-drive-system' 
        name='gz::sim::systems::DiffDrive'>
        <left_joint>base_to_left_wheel</left_joint>
        <right_joint>base_to_right_wheel</right_joint>
        <wheel_separation>0.95</wheel_separation>
        <wheel_radius>0.3</wheel_radius>
        <odom_publish_frequency>1</odom_publish_frequency>
        <topic>cmd_vel</topic>
      </plugin>
    <!-- Moving Backward-->
      <plugin filename="gz-sim-triggered-publisher-system"
              name="gz::sim::systems::TriggeredPublisher">
          <input type="gz.msgs.Int32" topic="/keyboard/keypress">
              <match field="data">16777237</match>
          </input>
          <output type="gz.msgs.Twist" topic="/cmd_vel">
              linear: {x: 0.5}, angular: {z: 0.0}
          </output>
      </plugin>
      <!-- Moving Forwart-->
      <plugin filename="gz-sim-triggered-publisher-system"
              name="gz::sim::systems::TriggeredPublisher">
          <input type="gz.msgs.Int32" topic="/keyboard/keypress">
              <match field="data">16777235</match>
          </input>
          <output type="gz.msgs.Twist" topic="/cmd_vel">
              linear: {x: -0.5}, angular: {z: 0.0}
          </output>
      </plugin>
    <!-- Moving Left-->
      <plugin filename="gz-sim-triggered-publisher-system"
              name="gz::sim::systems::TriggeredPublisher">
          <input type="gz.msgs.Int32" topic="/keyboard/keypress">
              <match field="data">16777234</match>
          </input>
          <output type="gz.msgs.Twist" topic="/cmd_vel">
              linear: {x: -0.1}, angular: {z: 0.9}
          </output>
      </plugin>
      <!-- Moving Right-->
      <plugin filename="gz-sim-triggered-publisher-system"
              name="gz::sim::systems::TriggeredPublisher">
          <input type="gz.msgs.Int32" topic="/keyboard/keypress">
              <match field="data">16777236</match>
          </input>
          <output type="gz.msgs.Twist" topic="/cmd_vel">
              linear: {x: 0.1}, angular: {z: -0.9}
          </output>
      </plugin>
      <pose>0.0012692599999999999 -1.10652e-07 0.39998 1.5631099999999998e-09 0.019972699999999993 -7.2983900000000048e-08</pose>
      <static>false</static>
      <self_collide>false</self_collide>
    </model>
    <light name='sun' type='directional'>
      <pose>0 0 10 0 0 0</pose>
      <cast_shadows>true</cast_shadows>
      <intensity>1</intensity>
      <direction>-0.5 0.10000000000000001 -0.90000000000000002</direction>
      <diffuse>0.800000012 0.800000012 0.800000012 1</diffuse>
      <specular>0.200000003 0.200000003 0.200000003 1</specular>
      <attenuation>
        <range>1000</range>
        <linear>0.0099999997764825821</linear>
        <constant>0.89999997615814209</constant>
        <quadratic>0.0010000000474974513</quadratic>
      </attenuation>
      <spot>
        <inner_angle>0</inner_angle>
        <outer_angle>0</outer_angle>
        <falloff>0</falloff>
      </spot>
    </light>
  </world>
</sdf>
